[2025-10-23T18:43:14.008+0000] {local_task_job_runner.py:120} INFO - ::group::Pre task execution logs
[2025-10-23T18:43:14.108+0000] {taskinstance.py:2076} INFO - Dependencies all met for dep_context=non-requeueable deps ti=<TaskInstance: airdna_etl_dag.extract1 manual__2025-10-23T18:37:56.997789+00:00 [queued]>
[2025-10-23T18:43:14.123+0000] {taskinstance.py:2076} INFO - Dependencies all met for dep_context=requeueable deps ti=<TaskInstance: airdna_etl_dag.extract1 manual__2025-10-23T18:37:56.997789+00:00 [queued]>
[2025-10-23T18:43:14.125+0000] {taskinstance.py:2306} INFO - Starting attempt 2 of 2
[2025-10-23T18:43:14.154+0000] {taskinstance.py:2330} INFO - Executing <Task(_PythonDecoratedOperator): extract1> on 2025-10-23 18:37:56.997789+00:00
[2025-10-23T18:43:14.187+0000] {standard_task_runner.py:63} INFO - Started process 281 to run task
[2025-10-23T18:43:14.198+0000] {standard_task_runner.py:90} INFO - Running: ['***', 'tasks', 'run', 'airdna_etl_dag', 'extract1', 'manual__2025-10-23T18:37:56.997789+00:00', '--job-id', '113', '--raw', '--subdir', 'DAGS_FOLDER/airbnb_etl_dag.py', '--cfg-path', '/tmp/tmpiyd941xj']
[2025-10-23T18:43:14.208+0000] {standard_task_runner.py:91} INFO - Job 113: Subtask extract1
[2025-10-23T18:43:14.374+0000] {task_command.py:426} INFO - Running <TaskInstance: airdna_etl_dag.extract1 manual__2025-10-23T18:37:56.997789+00:00 [running]> on host ae3d9fdb668e
[2025-10-23T18:43:14.620+0000] {taskinstance.py:2648} INFO - Exporting env vars: AIRFLOW_CTX_DAG_OWNER='***' AIRFLOW_CTX_DAG_ID='airdna_etl_dag' AIRFLOW_CTX_TASK_ID='extract1' AIRFLOW_CTX_EXECUTION_DATE='2025-10-23T18:37:56.997789+00:00' AIRFLOW_CTX_TRY_NUMBER='2' AIRFLOW_CTX_DAG_RUN_ID='manual__2025-10-23T18:37:56.997789+00:00'
[2025-10-23T18:43:14.623+0000] {taskinstance.py:430} INFO - ::endgroup::
[2025-10-23T18:43:14.632+0000] {taskinstance.py:441} INFO - ::group::Post task execution logs
[2025-10-23T18:43:14.634+0000] {taskinstance.py:2905} ERROR - Task failed with exception
Traceback (most recent call last):
  File "/home/airflow/.local/lib/python3.11/site-packages/airflow/models/taskinstance.py", line 465, in _execute_task
    result = _execute_callable(context=context, **execute_callable_kwargs)
             ^^^^^^^^^^^^^^^^^^^^^^^^^^^^^^^^^^^^^^^^^^^^^^^^^^^^^^^^^^^^^
  File "/home/airflow/.local/lib/python3.11/site-packages/airflow/models/taskinstance.py", line 432, in _execute_callable
    return execute_callable(context=context, **execute_callable_kwargs)
           ^^^^^^^^^^^^^^^^^^^^^^^^^^^^^^^^^^^^^^^^^^^^^^^^^^^^^^^^^^^^
  File "/home/airflow/.local/lib/python3.11/site-packages/airflow/models/baseoperator.py", line 401, in wrapper
    return func(self, *args, **kwargs)
           ^^^^^^^^^^^^^^^^^^^^^^^^^^^
  File "/home/airflow/.local/lib/python3.11/site-packages/airflow/decorators/base.py", line 265, in execute
    return_value = super().execute(context)
                   ^^^^^^^^^^^^^^^^^^^^^^^^
  File "/home/airflow/.local/lib/python3.11/site-packages/airflow/models/baseoperator.py", line 401, in wrapper
    return func(self, *args, **kwargs)
           ^^^^^^^^^^^^^^^^^^^^^^^^^^^
  File "/home/airflow/.local/lib/python3.11/site-packages/airflow/operators/python.py", line 235, in execute
    return_value = self.execute_callable()
                   ^^^^^^^^^^^^^^^^^^^^^^^
  File "/home/airflow/.local/lib/python3.11/site-packages/airflow/operators/python.py", line 252, in execute_callable
    return self.python_callable(*self.op_args, **self.op_kwargs)
           ^^^^^^^^^^^^^^^^^^^^^^^^^^^^^^^^^^^^^^^^^^^^^^^^^^^^^
  File "/opt/airflow/dags/airbnb_etl_dag.py", line 39, in extract1
    API_KEY = API_KEY
              ^^^^^^^
UnboundLocalError: cannot access local variable 'API_KEY' where it is not associated with a value
[2025-10-23T18:43:14.671+0000] {taskinstance.py:1206} INFO - Marking task as FAILED. dag_id=airdna_etl_dag, task_id=extract1, run_id=manual__2025-10-23T18:37:56.997789+00:00, execution_date=20251023T183756, start_date=20251023T184314, end_date=20251023T184314
[2025-10-23T18:43:14.702+0000] {standard_task_runner.py:110} ERROR - Failed to execute job 113 for task extract1 (cannot access local variable 'API_KEY' where it is not associated with a value; 281)
[2025-10-23T18:43:14.739+0000] {local_task_job_runner.py:240} INFO - Task exited with return code 1
[2025-10-23T18:43:14.815+0000] {taskinstance.py:3503} INFO - 0 downstream tasks scheduled from follow-on schedule check
[2025-10-23T18:43:14.829+0000] {local_task_job_runner.py:222} INFO - ::endgroup::
