[2025-10-23T18:19:08.621+0000] {local_task_job_runner.py:120} INFO - ::group::Pre task execution logs
[2025-10-23T18:19:08.738+0000] {taskinstance.py:2076} INFO - Dependencies all met for dep_context=non-requeueable deps ti=<TaskInstance: airdna_etl_dag.extract2 manual__2025-10-23T18:04:55.489569+00:00 [queued]>
[2025-10-23T18:19:08.769+0000] {taskinstance.py:2076} INFO - Dependencies all met for dep_context=requeueable deps ti=<TaskInstance: airdna_etl_dag.extract2 manual__2025-10-23T18:04:55.489569+00:00 [queued]>
[2025-10-23T18:19:08.772+0000] {taskinstance.py:2306} INFO - Starting attempt 2 of 2
[2025-10-23T18:19:08.849+0000] {taskinstance.py:2330} INFO - Executing <Task(_PythonDecoratedOperator): extract2> on 2025-10-23 18:04:55.489569+00:00
[2025-10-23T18:19:08.921+0000] {standard_task_runner.py:63} INFO - Started process 179 to run task
[2025-10-23T18:19:08.945+0000] {standard_task_runner.py:90} INFO - Running: ['***', 'tasks', 'run', 'airdna_etl_dag', 'extract2', 'manual__2025-10-23T18:04:55.489569+00:00', '--job-id', '107', '--raw', '--subdir', 'DAGS_FOLDER/airbnb_etl_dag.py', '--cfg-path', '/tmp/tmplpmid0iu']
[2025-10-23T18:19:08.966+0000] {standard_task_runner.py:91} INFO - Job 107: Subtask extract2
[2025-10-23T18:19:09.239+0000] {task_command.py:426} INFO - Running <TaskInstance: airdna_etl_dag.extract2 manual__2025-10-23T18:04:55.489569+00:00 [running]> on host c057558233af
[2025-10-23T18:19:09.697+0000] {taskinstance.py:2648} INFO - Exporting env vars: AIRFLOW_CTX_DAG_OWNER='***' AIRFLOW_CTX_DAG_ID='airdna_etl_dag' AIRFLOW_CTX_TASK_ID='extract2' AIRFLOW_CTX_EXECUTION_DATE='2025-10-23T18:04:55.489569+00:00' AIRFLOW_CTX_TRY_NUMBER='2' AIRFLOW_CTX_DAG_RUN_ID='manual__2025-10-23T18:04:55.489569+00:00'
[2025-10-23T18:19:09.707+0000] {taskinstance.py:430} INFO - ::endgroup::
[2025-10-23T18:19:09.710+0000] {taskinstance.py:441} INFO - ::group::Post task execution logs
[2025-10-23T18:19:09.714+0000] {taskinstance.py:2905} ERROR - Task failed with exception
Traceback (most recent call last):
  File "/home/airflow/.local/lib/python3.11/site-packages/airflow/models/taskinstance.py", line 465, in _execute_task
    result = _execute_callable(context=context, **execute_callable_kwargs)
             ^^^^^^^^^^^^^^^^^^^^^^^^^^^^^^^^^^^^^^^^^^^^^^^^^^^^^^^^^^^^^
  File "/home/airflow/.local/lib/python3.11/site-packages/airflow/models/taskinstance.py", line 432, in _execute_callable
    return execute_callable(context=context, **execute_callable_kwargs)
           ^^^^^^^^^^^^^^^^^^^^^^^^^^^^^^^^^^^^^^^^^^^^^^^^^^^^^^^^^^^^
  File "/home/airflow/.local/lib/python3.11/site-packages/airflow/models/baseoperator.py", line 401, in wrapper
    return func(self, *args, **kwargs)
           ^^^^^^^^^^^^^^^^^^^^^^^^^^^
  File "/home/airflow/.local/lib/python3.11/site-packages/airflow/decorators/base.py", line 265, in execute
    return_value = super().execute(context)
                   ^^^^^^^^^^^^^^^^^^^^^^^^
  File "/home/airflow/.local/lib/python3.11/site-packages/airflow/models/baseoperator.py", line 401, in wrapper
    return func(self, *args, **kwargs)
           ^^^^^^^^^^^^^^^^^^^^^^^^^^^
  File "/home/airflow/.local/lib/python3.11/site-packages/airflow/operators/python.py", line 235, in execute
    return_value = self.execute_callable()
                   ^^^^^^^^^^^^^^^^^^^^^^^
  File "/home/airflow/.local/lib/python3.11/site-packages/airflow/operators/python.py", line 252, in execute_callable
    return self.python_callable(*self.op_args, **self.op_kwargs)
           ^^^^^^^^^^^^^^^^^^^^^^^^^^^^^^^^^^^^^^^^^^^^^^^^^^^^^
  File "/opt/airflow/dags/airbnb_etl_dag.py", line 163, in extract2
    API_KEY = API_KEY
              ^^^^^^^
UnboundLocalError: cannot access local variable 'API_KEY' where it is not associated with a value
[2025-10-23T18:19:09.838+0000] {taskinstance.py:1206} INFO - Marking task as FAILED. dag_id=airdna_etl_dag, task_id=extract2, run_id=manual__2025-10-23T18:04:55.489569+00:00, execution_date=20251023T180455, start_date=20251023T181908, end_date=20251023T181909
[2025-10-23T18:19:09.920+0000] {standard_task_runner.py:110} ERROR - Failed to execute job 107 for task extract2 (cannot access local variable 'API_KEY' where it is not associated with a value; 179)
[2025-10-23T18:19:09.968+0000] {local_task_job_runner.py:240} INFO - Task exited with return code 1
[2025-10-23T18:19:10.113+0000] {taskinstance.py:3503} INFO - 0 downstream tasks scheduled from follow-on schedule check
[2025-10-23T18:19:10.138+0000] {local_task_job_runner.py:222} INFO - ::endgroup::
